Workbook

Sheet 04 — Scenario comparison — Base
A1: 04 — Scenario comparison — Base is Main Scenario
A2: TicketStub — neatHack Business Plan — 2026-10-11 · Main Scenario
A4: Variable / dimension | B4: Value | C4: Value > TicketStub — Conservative | D4: Value > TicketStub — Growth
A5: TS Monthly visits | B5: =10000 -> 10000 | C5: =5000 -> 5000 | D5: =25000 -> 25000
A6: TS Studio start rate | B6: =0.1 -> 0.1 | C6: ='04 — Scenario comparison — Base'!B6 -> 0.1 | D6: ='04 — Scenario comparison — Base'!B6 -> 0.1
A7: TS Paid conversion of visits | B7: =0.02 -> 0.02 | C7: =0.01 -> 0.01 | D7: =0.04 -> 0.04
A8: TS Images per start | B8: ='01 — Editable assumptions — USD'!B8+'01 — Editable assumptions — USD'!B9 -> 2 | C8: ='Model inputs'!B69+'Model inputs'!B28 -> 4 | D8: ='Model inputs'!B68+'Model inputs'!B27 -> 1.5
A9: TS Chats per start | B9: =4 -> 4 | C9: =8 -> 8 | D9: =3 -> 3
A10: TS Digital orders | B10: ='04 — Scenario comparison — Base'!B5*'04 — Scenario comparison — Base'!B7 -> 200 | C10: ='04 — Scenario comparison — Base'!C5*'04 — Scenario comparison — Base'!C7 -> 50 | D10: ='04 — Scenario comparison — Base'!D5*'04 — Scenario comparison — Base'!D7 -> 1000
A11: TS Studio starts | B11: ='04 — Scenario comparison — Base'!B5*'04 — Scenario comparison — Base'!B6 -> 1000 | C11: ='04 — Scenario comparison — Base'!C5*'04 — Scenario comparison — Base'!C6 -> 500 | D11: ='04 — Scenario comparison — Base'!D5*'04 — Scenario comparison — Base'!D6 -> 2500
A12: TS Monthly digital revenue | B12: ='04 — Scenario comparison — Base'!B10*'01 — Editable assumptions — USD'!B11 -> 1800 | C12: ='04 — Scenario comparison — Base'!C10*'Model inputs'!B24 -> 450 | D12: ='04 — Scenario comparison — Base'!D10*'Model inputs'!B23 -> 9000
A13: TS Monthly AI spend | B13: ='04 — Scenario comparison — Base'!B11*'03 — Digital unit economics and'!B9 -> 308.99 | C13: ='04 — Scenario comparison — Base'!C11*'Model inputs'!B8 -> 301.57 | D13: ='04 — Scenario comparison — Base'!D11*'Model inputs'!B7 -> 588.63125
A14: TS AI cost per paid order | B14: =IFERROR('04 — Scenario comparison — Base'!B13/'04 — Scenario comparison — Base'!B10,"") -> 1.54495 | C14: =IFERROR('04 — Scenario comparison — Base'!C13/'04 — Scenario comparison — Base'!C10,"") -> 6.0314 | D14: =IFERROR('04 — Scenario comparison — Base'!D13/'04 — Scenario comparison — Base'!D10,"") -> 0.58863125
A15: TS Digital contribution per order | B15: ='01 — Editable assumptions — USD'!B11-'03 — Digital unit economics and'!B15-'03 — Digital unit economics and'!B16-'03 — Digital unit economics and'!B17-'04 — Scenario comparison — Base'!B14 -> 6.51405 | C15: ='Model inputs'!B24-'Model inputs'!B86-'Model inputs'!B110-'Model inputs'!B113-'04 — Scenario comparison — Base'!C14 -> 2.0276 | D15: ='Model inputs'!B23-'Model inputs'!B85-'Model inputs'!B109-'Model inputs'!B112-'04 — Scenario comparison — Base'!D14 -> 7.4703688
A16: TS Digital contribution margin | B16: =IFERROR('04 — Scenario comparison — Base'!B15/'01 — Editable assumptions — USD'!B11,"") -> 0.72378333 | C16: =IFERROR('04 — Scenario comparison — Base'!C15/'Model inputs'!B24,"") -> 0.22528889 | D16: =IFERROR('04 — Scenario comparison — Base'!D15/'Model inputs'!B23,"") -> 0.83004097
A17: TS Fixed monthly budget | B17: =SUM('02 — Fixed monthly budgets — es'!B5,'02 — Fixed monthly budgets — es'!B6,'02 — Fixed monthly budgets — es'!B7,'02 — Fixed monthly budgets — es'!B8,'02 — Fixed monthly budgets — es'!B9,'02 — Fixed monthly budgets — es'!B10,'02 — Fixed monthly budgets — es'!B11) -> 300 | C17: =SUM('Model inputs'!B46,'Model inputs'!B47,'Model inputs'!B48,'Model inputs'!B49,'Model inputs'!B50,'Model inputs'!B51,'Model inputs'!B52) -> 150 | D17: =SUM('Model inputs'!B38,'Model inputs'!B39,'Model inputs'!B40,'Model inputs'!B41,'Model inputs'!B42,'Model inputs'!B43,'Model inputs'!B44) -> 900
A18: TS Monthly marketing | B18: =300 -> 300 | C18: =100 -> 100 | D18: =1500 -> 1500
A19: TS Monthly operating profit bootstrap | B19: ='03 — Digital unit economics and'!B20-'04 — Scenario comparison — Base'!B17-'04 — Scenario comparison — Base'!B18-'01 — Editable assumptions — USD'!B36 -> 702.81 | C19: ='Model inputs'!B77-'04 — Scenario comparison — Base'!C17-'04 — Scenario comparison — Base'!C18-'Model inputs'!B58 -> -148.62 | D19: ='Model inputs'!B76-'04 — Scenario comparison — Base'!D17-'04 — Scenario comparison — Base'!D18-'Model inputs'!B57 -> 5070.3688
A20: TS Monthly operating profit founder | B20: ='03 — Digital unit economics and'!B20-'04 — Scenario comparison — Base'!B17-'04 — Scenario comparison — Base'!B18-'01 — Editable assumptions — USD'!B37 -> -2297.19 | C20: ='Model inputs'!B77-'04 — Scenario comparison — Base'!C17-'04 — Scenario comparison — Base'!C18-'Model inputs'!B62 -> -3148.62 | D20: ='Model inputs'!B76-'04 — Scenario comparison — Base'!D17-'04 — Scenario comparison — Base'!D18-'Model inputs'!B61 -> 2070.3688
A21: TS Break-even orders bootstrap | B21: =IF(IF(IF(ISERROR('04 — Scenario comparison — Base'!B15>0),'04 — Scenario comparison — Base'!B15>0,IF('04 — Scenario comparison — Base'!B15="","",'04 — Scenario comparison — Base'!B15>0))="",FALSE,IF(ISERROR('04 — Scenario comparison — Base'!B15>0),'04 — Scenario comparison — Base'!B15>0,IF('04 — Scenario comparison — Base'!B15="","",'04 — Scenario comparison — Base'!B15>0))),CEILING(('04 — Scenario comparison — Base'!B17+'04 — Scenario comparison — Base'!B18+'01 — Editable assumptions — USD'!B36)/'04 — Scenario comparison — Base'!B15,1),"") -> 93 | C21: =IF(IF(IF(ISERROR('04 — Scenario comparison — Base'!C15>0),'04 — Scenario comparison — Base'!C15>0,IF('04 — Scenario comparison — Base'!C15="","",'04 — Scenario comparison — Base'!C15>0))="",FALSE,IF(ISERROR('04 — Scenario comparison — Base'!C15>0),'04 — Scenario comparison — Base'!C15>0,IF('04 — Scenario comparison — Base'!C15="","",'04 — Scenario comparison — Base'!C15>0))),CEILING(('04 — Scenario comparison — Base'!C17+'04 — Scenario comparison — Base'!C18+'Model inputs'!B58)/'04 — Scenario comparison — Base'!C15,1),"") -> 124 | D21: =IF(IF(IF(ISERROR('04 — Scenario comparison — Base'!D15>0),'04 — Scenario comparison — Base'!D15>0,IF('04 — Scenario comparison — Base'!D15="","",'04 — Scenario comparison — Base'!D15>0))="",FALSE,IF(ISERROR('04 — Scenario comparison — Base'!D15>0),'04 — Scenario comparison — Base'!D15>0,IF('04 — Scenario comparison — Base'!D15="","",'04 — Scenario comparison — Base'!D15>0))),CEILING(('04 — Scenario comparison — Base'!D17+'04 — Scenario comparison — Base'!D18+'Model inputs'!B57)/'04 — Scenario comparison — Base'!D15,1),"") -> 322
A22: TS Break-even orders founder | B22: =IF(IF(IF(ISERROR('04 — Scenario comparison — Base'!B15>0),'04 — Scenario comparison — Base'!B15>0,IF('04 — Scenario comparison — Base'!B15="","",'04 — Scenario comparison — Base'!B15>0))="",FALSE,IF(ISERROR('04 — Scenario comparison — Base'!B15>0),'04 — Scenario comparison — Base'!B15>0,IF('04 — Scenario comparison — Base'!B15="","",'04 — Scenario comparison — Base'!B15>0))),CEILING(('04 — Scenario comparison — Base'!B17+'04 — Scenario comparison — Base'!B18+'01 — Editable assumptions — USD'!B37)/'04 — Scenario comparison — Base'!B15,1),"") -> 553 | C22: =IF(IF(IF(ISERROR('04 — Scenario comparison — Base'!C15>0),'04 — Scenario comparison — Base'!C15>0,IF('04 — Scenario comparison — Base'!C15="","",'04 — Scenario comparison — Base'!C15>0))="",FALSE,IF(ISERROR('04 — Scenario comparison — Base'!C15>0),'04 — Scenario comparison — Base'!C15>0,IF('04 — Scenario comparison — Base'!C15="","",'04 — Scenario comparison — Base'!C15>0))),CEILING(('04 — Scenario comparison — Base'!C17+'04 — Scenario comparison — Base'!C18+'Model inputs'!B62)/'04 — Scenario comparison — Base'!C15,1),"") -> 1603 | D22: =IF(IF(IF(ISERROR('04 — Scenario comparison — Base'!D15>0),'04 — Scenario comparison — Base'!D15>0,IF('04 — Scenario comparison — Base'!D15="","",'04 — Scenario comparison — Base'!D15>0))="",FALSE,IF(ISERROR('04 — Scenario comparison — Base'!D15>0),'04 — Scenario comparison — Base'!D15>0,IF('04 — Scenario comparison — Base'!D15="","",'04 — Scenario comparison — Base'!D15>0))),CEILING(('04 — Scenario comparison — Base'!D17+'04 — Scenario comparison — Base'!D18+'Model inputs'!B61)/'04 — Scenario comparison — Base'!D15,1),"") -> 723
A23: TS Launch reserve | B23: ='01 — Editable assumptions — USD'!B38+'01 — Editable assumptions — USD'!B39/'01 — Editable assumptions — USD'!B40*'03 — Digital unit economics and'!B21 -> 616.011 | C23: ='Model inputs'!B18+'Model inputs'!B89/'Model inputs'!B15*'Model inputs'!B83 -> 581.34467 | D23: ='Model inputs'!B17+'Model inputs'!B88/'Model inputs'!B14*'Model inputs'!B82 -> 856.91396
A24: TS Hypothetical opening cash | B24: =1000 -> 1000 | C24: ='04 — Scenario comparison — Base'!B24 -> 1000 | D24: ='04 — Scenario comparison — Base'!B24 -> 1000
A25: TS Launch status | B25: =IF(IF(IF(ISERROR('04 — Scenario comparison — Base'!B24<'04 — Scenario comparison — Base'!B23),'04 — Scenario comparison — Base'!B24<'04 — Scenario comparison — Base'!B23,IF(OR('04 — Scenario comparison — Base'!B24="",'04 — Scenario comparison — Base'!B23=""),"",'04 — Scenario comparison — Base'!B24<'04 — Scenario comparison — Base'!B23))="",FALSE,IF(ISERROR('04 — Scenario comparison — Base'!B24<'04 — Scenario comparison — Base'!B23),'04 — Scenario comparison — Base'!B24<'04 — Scenario comparison — Base'!B23,IF(OR('04 — Scenario comparison — Base'!B24="",'04 — Scenario comparison — Base'!B23=""),"",'04 — Scenario comparison — Base'!B24<'04 — Scenario comparison — Base'!B23))),"UNFUNDED LAUNCH","Reserve funded; ramp still required") -> Reserve funded; ramp still required | C25: =IF(IF(IF(ISERROR('04 — Scenario comparison — Base'!C24<'04 — Scenario comparison — Base'!C23),'04 — Scenario comparison — Base'!C24<'04 — Scenario comparison — Base'!C23,IF(OR('04 — Scenario comparison — Base'!C24="",'04 — Scenario comparison — Base'!C23=""),"",'04 — Scenario comparison — Base'!C24<'04 — Scenario comparison — Base'!C23))="",FALSE,IF(ISERROR('04 — Scenario comparison — Base'!C24<'04 — Scenario comparison — Base'!C23),'04 — Scenario comparison — Base'!C24<'04 — Scenario comparison — Base'!C23,IF(OR('04 — Scenario comparison — Base'!C24="",'04 — Scenario comparison — Base'!C23=""),"",'04 — Scenario comparison — Base'!C24<'04 — Scenario comparison — Base'!C23))),"UNFUNDED LAUNCH","Reserve funded; ramp still required") -> Reserve funded; ramp still required | D25: =IF(IF(IF(ISERROR('04 — Scenario comparison — Base'!D24<'04 — Scenario comparison — Base'!D23),'04 — Scenario comparison — Base'!D24<'04 — Scenario comparison — Base'!D23,IF(OR('04 — Scenario comparison — Base'!D24="",'04 — Scenario comparison — Base'!D23=""),"",'04 — Scenario comparison — Base'!D24<'04 — Scenario comparison — Base'!D23))="",FALSE,IF(ISERROR('04 — Scenario comparison — Base'!D24<'04 — Scenario comparison — Base'!D23),'04 — Scenario comparison — Base'!D24<'04 — Scenario comparison — Base'!D23,IF(OR('04 — Scenario comparison — Base'!D24="",'04 — Scenario comparison — Base'!D23=""),"",'04 — Scenario comparison — Base'!D24<'04 — Scenario comparison — Base'!D23))),"UNFUNDED LAUNCH","Reserve funded; ramp still required") -> Reserve funded; ramp still required
A26: TS Zero cash launch status | B26: =IF(IF(IF(ISERROR('01 — Editable assumptions — USD'!B34<'04 — Scenario comparison — Base'!B23),'01 — Editable assumptions — USD'!B34<'04 — Scenario comparison — Base'!B23,IF(OR('01 — Editable assumptions — USD'!B34="",'04 — Scenario comparison — Base'!B23=""),"",'01 — Editable assumptions — USD'!B34<'04 — Scenario comparison — Base'!B23))="",FALSE,IF(ISERROR('01 — Editable assumptions — USD'!B34<'04 — Scenario comparison — Base'!B23),'01 — Editable assumptions — USD'!B34<'04 — Scenario comparison — Base'!B23,IF(OR('01 — Editable assumptions — USD'!B34="",'04 — Scenario comparison — Base'!B23=""),"",'01 — Editable assumptions — USD'!B34<'04 — Scenario comparison — Base'!B23))),"UNFUNDED LAUNCH","Reserve funded; ramp still required") -> UNFUNDED LAUNCH | C26: =IF(IF(IF(ISERROR('Model inputs'!B12<'04 — Scenario comparison — Base'!C23),'Model inputs'!B12<'04 — Scenario comparison — Base'!C23,IF(OR('Model inputs'!B12="",'04 — Scenario comparison — Base'!C23=""),"",'Model inputs'!B12<'04 — Scenario comparison — Base'!C23))="",FALSE,IF(ISERROR('Model inputs'!B12<'04 — Scenario comparison — Base'!C23),'Model inputs'!B12<'04 — Scenario comparison — Base'!C23,IF(OR('Model inputs'!B12="",'04 — Scenario comparison — Base'!C23=""),"",'Model inputs'!B12<'04 — Scenario comparison — Base'!C23))),"UNFUNDED LAUNCH","Reserve funded; ramp still required") -> UNFUNDED LAUNCH | D26: =IF(IF(IF(ISERROR('Model inputs'!B11<'04 — Scenario comparison — Base'!D23),'Model inputs'!B11<'04 — Scenario comparison — Base'!D23,IF(OR('Model inputs'!B11="",'04 — Scenario comparison — Base'!D23=""),"",'Model inputs'!B11<'04 — Scenario comparison — Base'!D23))="",FALSE,IF(ISERROR('Model inputs'!B11<'04 — Scenario comparison — Base'!D23),'Model inputs'!B11<'04 — Scenario comparison — Base'!D23,IF(OR('Model inputs'!B11="",'04 — Scenario comparison — Base'!D23=""),"",'Model inputs'!B11<'04 — Scenario comparison — Base'!D23))),"UNFUNDED LAUNCH","Reserve funded; ramp still required") -> UNFUNDED LAUNCH
A27: TS Runway months bootstrap | B27: =IF(IF(IF(ISERROR('03 — Digital unit economics and'!B29>0),'03 — Digital unit economics and'!B29>0,IF('03 — Digital unit economics and'!B29="","",'03 — Digital unit economics and'!B29>0))="",FALSE,IF(ISERROR('03 — Digital unit economics and'!B29>0),'03 — Digital unit economics and'!B29>0,IF('03 — Digital unit economics and'!B29="","",'03 — Digital unit economics and'!B29>0))),MAX(0,'04 — Scenario comparison — Base'!B24-'04 — Scenario comparison — Base'!B23)/'03 — Digital unit economics and'!B29,"") | C27: =IF(IF(IF(ISERROR('Model inputs'!B73>0),'Model inputs'!B73>0,IF('Model inputs'!B73="","",'Model inputs'!B73>0))="",FALSE,IF(ISERROR('Model inputs'!B73>0),'Model inputs'!B73>0,IF('Model inputs'!B73="","",'Model inputs'!B73>0))),MAX(0,'04 — Scenario comparison — Base'!C24-'04 — Scenario comparison — Base'!C23)/'Model inputs'!B73,"") -> 2.8169515 | D27: =IF(IF(IF(ISERROR('Model inputs'!B72>0),'Model inputs'!B72>0,IF('Model inputs'!B72="","",'Model inputs'!B72>0))="",FALSE,IF(ISERROR('Model inputs'!B72>0),'Model inputs'!B72>0,IF('Model inputs'!B72="","",'Model inputs'!B72>0))),MAX(0,'04 — Scenario comparison — Base'!D24-'04 — Scenario comparison — Base'!D23)/'Model inputs'!B72,"")
A28: TS Runway months founder | B28: =IF(IF(IF(ISERROR('03 — Digital unit economics and'!B30>0),'03 — Digital unit economics and'!B30>0,IF('03 — Digital unit economics and'!B30="","",'03 — Digital unit economics and'!B30>0))="",FALSE,IF(ISERROR('03 — Digital unit economics and'!B30>0),'03 — Digital unit economics and'!B30>0,IF('03 — Digital unit economics and'!B30="","",'03 — Digital unit economics and'!B30>0))),MAX(0,'04 — Scenario comparison — Base'!B24-'04 — Scenario comparison — Base'!B23)/'03 — Digital unit economics and'!B30,"") -> 0.16715596 | C28: =IF(IF(IF(ISERROR('Model inputs'!B75>0),'Model inputs'!B75>0,IF('Model inputs'!B75="","",'Model inputs'!B75>0))="",FALSE,IF(ISERROR('Model inputs'!B75>0),'Model inputs'!B75>0,IF('Model inputs'!B75="","",'Model inputs'!B75>0))),MAX(0,'04 — Scenario comparison — Base'!C24-'04 — Scenario comparison — Base'!C23)/'Model inputs'!B75,"") -> 0.13296471 | D28: =IF(IF(IF(ISERROR('Model inputs'!B74>0),'Model inputs'!B74>0,IF('Model inputs'!B74="","",'Model inputs'!B74>0))="",FALSE,IF(ISERROR('Model inputs'!B74>0),'Model inputs'!B74>0,IF('Model inputs'!B74="","",'Model inputs'!B74>0))),MAX(0,'04 — Scenario comparison — Base'!D24-'04 — Scenario comparison — Base'!D23)/'Model inputs'!B74,"")
A29: TS Runway at funded bootstrap | B29: =IF(IF(IF(ISERROR('03 — Digital unit economics and'!B29>0),'03 — Digital unit economics and'!B29>0,IF('03 — Digital unit economics and'!B29="","",'03 — Digital unit economics and'!B29>0))="",FALSE,IF(ISERROR('03 — Digital unit economics and'!B29>0),'03 — Digital unit economics and'!B29>0,IF('03 — Digital unit economics and'!B29="","",'03 — Digital unit economics and'!B29>0))),MAX(0,'01 — Editable assumptions — USD'!B35-'04 — Scenario comparison — Base'!B23)/'03 — Digital unit economics and'!B29,"") | C29: =IF(IF(IF(ISERROR('Model inputs'!B73>0),'Model inputs'!B73>0,IF('Model inputs'!B73="","",'Model inputs'!B73>0))="",FALSE,IF(ISERROR('Model inputs'!B73>0),'Model inputs'!B73>0,IF('Model inputs'!B73="","",'Model inputs'!B73>0))),MAX(0,'Model inputs'!B10-'04 — Scenario comparison — Base'!C23)/'Model inputs'!B73,"") -> 29.73123 | D29: =IF(IF(IF(ISERROR('Model inputs'!B72>0),'Model inputs'!B72>0,IF('Model inputs'!B72="","",'Model inputs'!B72>0))="",FALSE,IF(ISERROR('Model inputs'!B72>0),'Model inputs'!B72>0,IF('Model inputs'!B72="","",'Model inputs'!B72>0))),MAX(0,'Model inputs'!B9-'04 — Scenario comparison — Base'!D23)/'Model inputs'!B72,"")
A30: TS Runway at funded founder | B30: =IF(IF(IF(ISERROR('03 — Digital unit economics and'!B30>0),'03 — Digital unit economics and'!B30>0,IF('03 — Digital unit economics and'!B30="","",'03 — Digital unit economics and'!B30>0))="",FALSE,IF(ISERROR('03 — Digital unit economics and'!B30>0),'03 — Digital unit economics and'!B30>0,IF('03 — Digital unit economics and'!B30="","",'03 — Digital unit economics and'!B30>0))),MAX(0,'01 — Editable assumptions — USD'!B35-'04 — Scenario comparison — Base'!B23)/'03 — Digital unit economics and'!B30,"") -> 1.9084138 | C30: =IF(IF(IF(ISERROR('Model inputs'!B75>0),'Model inputs'!B75>0,IF('Model inputs'!B75="","",'Model inputs'!B75>0))="",FALSE,IF(ISERROR('Model inputs'!B75>0),'Model inputs'!B75>0,IF('Model inputs'!B75="","",'Model inputs'!B75>0))),MAX(0,'Model inputs'!B10-'04 — Scenario comparison — Base'!C23)/'Model inputs'!B75,"") -> 1.4033625 | D30: =IF(IF(IF(ISERROR('Model inputs'!B74>0),'Model inputs'!B74>0,IF('Model inputs'!B74="","",'Model inputs'!B74>0))="",FALSE,IF(ISERROR('Model inputs'!B74>0),'Model inputs'!B74>0,IF('Model inputs'!B74="","",'Model inputs'!B74>0))),MAX(0,'Model inputs'!B9-'04 — Scenario comparison — Base'!D23)/'Model inputs'!B74,"")
A31: TS Bootstrap runway interpretation | B31: =IF(IF(IF(ISERROR('04 — Scenario comparison — Base'!B24<'04 — Scenario comparison — Base'!B23),'04 — Scenario comparison — Base'!B24<'04 — Scenario comparison — Base'!B23,IF(OR('04 — Scenario comparison — Base'!B24="",'04 — Scenario comparison — Base'!B23=""),"",'04 — Scenario comparison — Base'!B24<'04 — Scenario comparison — Base'!B23))="",FALSE,IF(ISERROR('04 — Scenario comparison — Base'!B24<'04 — Scenario comparison — Base'!B23),'04 — Scenario comparison — Base'!B24<'04 — Scenario comparison — Base'!B23,IF(OR('04 — Scenario comparison — Base'!B24="",'04 — Scenario comparison — Base'!B23=""),"",'04 — Scenario comparison — Base'!B24<'04 — Scenario comparison — Base'!B23))),"UNFUNDED LAUNCH",IF(IF(IF(ISERROR('03 — Digital unit economics and'!B29=0),'03 — Digital unit economics and'!B29=0,IF('03 — Digital unit economics and'!B29="","",'03 — Digital unit economics and'!B29=0))="",FALSE,IF(ISERROR('03 — Digital unit economics and'!B29=0),'03 — Digital unit economics and'!B29=0,IF('03 — Digital unit economics and'!B29="","",'03 — Digital unit economics and'!B29=0))),"Cash-positive steady state; not guaranteed runway","Finite burn runway; steady-state assumption")) -> Cash-positive steady state; not guaranteed runway | C31: =IF(IF(IF(ISERROR('04 — Scenario comparison — Base'!C24<'04 — Scenario comparison — Base'!C23),'04 — Scenario comparison — Base'!C24<'04 — Scenario comparison — Base'!C23,IF(OR('04 — Scenario comparison — Base'!C24="",'04 — Scenario comparison — Base'!C23=""),"",'04 — Scenario comparison — Base'!C24<'04 — Scenario comparison — Base'!C23))="",FALSE,IF(ISERROR('04 — Scenario comparison — Base'!C24<'04 — Scenario comparison — Base'!C23),'04 — Scenario comparison — Base'!C24<'04 — Scenario comparison — Base'!C23,IF(OR('04 — Scenario comparison — Base'!C24="",'04 — Scenario comparison — Base'!C23=""),"",'04 — Scenario comparison — Base'!C24<'04 — Scenario comparison — Base'!C23))),"UNFUNDED LAUNCH",IF(IF(IF(ISERROR('Model inputs'!B73=0),'Model inputs'!B73=0,IF('Model inputs'!B73="","",'Model inputs'!B73=0))="",FALSE,IF(ISERROR('Model inputs'!B73=0),'Model inputs'!B73=0,IF('Model inputs'!B73="","",'Model inputs'!B73=0))),"Cash-positive steady state; not guaranteed runway","Finite burn runway; steady-state assumption")) -> Finite burn runway; steady-state assumption | D31: =IF(IF(IF(ISERROR('04 — Scenario comparison — Base'!D24<'04 — Scenario comparison — Base'!D23),'04 — Scenario comparison — Base'!D24<'04 — Scenario comparison — Base'!D23,IF(OR('04 — Scenario comparison — Base'!D24="",'04 — Scenario comparison — Base'!D23=""),"",'04 — Scenario comparison — Base'!D24<'04 — Scenario comparison — Base'!D23))="",FALSE,IF(ISERROR('04 — Scenario comparison — Base'!D24<'04 — Scenario comparison — Base'!D23),'04 — Scenario comparison — Base'!D24<'04 — Scenario comparison — Base'!D23,IF(OR('04 — Scenario comparison — Base'!D24="",'04 — Scenario comparison — Base'!D23=""),"",'04 — Scenario comparison — Base'!D24<'04 — Scenario comparison — Base'!D23))),"UNFUNDED LAUNCH",IF(IF(IF(ISERROR('Model inputs'!B72=0),'Model inputs'!B72=0,IF('Model inputs'!B72="","",'Model inputs'!B72=0))="",FALSE,IF(ISERROR('Model inputs'!B72=0),'Model inputs'!B72=0,IF('Model inputs'!B72="","",'Model inputs'!B72=0))),"Cash-positive steady state; not guaranteed runway","Finite burn runway; steady-state assumption")) -> Cash-positive steady state; not guaranteed runway
A32: TS Founder runway interpretation | B32: =IF(IF(IF(ISERROR('04 — Scenario comparison — Base'!B24<'04 — Scenario comparison — Base'!B23),'04 — Scenario comparison — Base'!B24<'04 — Scenario comparison — Base'!B23,IF(OR('04 — Scenario comparison — Base'!B24="",'04 — Scenario comparison — Base'!B23=""),"",'04 — Scenario comparison — Base'!B24<'04 — Scenario comparison — Base'!B23))="",FALSE,IF(ISERROR('04 — Scenario comparison — Base'!B24<'04 — Scenario comparison — Base'!B23),'04 — Scenario comparison — Base'!B24<'04 — Scenario comparison — Base'!B23,IF(OR('04 — Scenario comparison — Base'!B24="",'04 — Scenario comparison — Base'!B23=""),"",'04 — Scenario comparison — Base'!B24<'04 — Scenario comparison — Base'!B23))),"UNFUNDED LAUNCH",IF(IF(IF(ISERROR('03 — Digital unit economics and'!B30=0),'03 — Digital unit economics and'!B30=0,IF('03 — Digital unit economics and'!B30="","",'03 — Digital unit economics and'!B30=0))="",FALSE,IF(ISERROR('03 — Digital unit economics and'!B30=0),'03 — Digital unit economics and'!B30=0,IF('03 — Digital unit economics and'!B30="","",'03 — Digital unit economics and'!B30=0))),"Cash-positive steady state; not guaranteed runway","Finite burn runway; steady-state assumption")) -> Finite burn runway; steady-state assumption | C32: =IF(IF(IF(ISERROR('04 — Scenario comparison — Base'!C24<'04 — Scenario comparison — Base'!C23),'04 — Scenario comparison — Base'!C24<'04 — Scenario comparison — Base'!C23,IF(OR('04 — Scenario comparison — Base'!C24="",'04 — Scenario comparison — Base'!C23=""),"",'04 — Scenario comparison — Base'!C24<'04 — Scenario comparison — Base'!C23))="",FALSE,IF(ISERROR('04 — Scenario comparison — Base'!C24<'04 — Scenario comparison — Base'!C23),'04 — Scenario comparison — Base'!C24<'04 — Scenario comparison — Base'!C23,IF(OR('04 — Scenario comparison — Base'!C24="",'04 — Scenario comparison — Base'!C23=""),"",'04 — Scenario comparison — Base'!C24<'04 — Scenario comparison — Base'!C23))),"UNFUNDED LAUNCH",IF(IF(IF(ISERROR('Model inputs'!B75=0),'Model inputs'!B75=0,IF('Model inputs'!B75="","",'Model inputs'!B75=0))="",FALSE,IF(ISERROR('Model inputs'!B75=0),'Model inputs'!B75=0,IF('Model inputs'!B75="","",'Model inputs'!B75=0))),"Cash-positive steady state; not guaranteed runway","Finite burn runway; steady-state assumption")) -> Finite burn runway; steady-state assumption | D32: =IF(IF(IF(ISERROR('04 — Scenario comparison — Base'!D24<'04 — Scenario comparison — Base'!D23),'04 — Scenario comparison — Base'!D24<'04 — Scenario comparison — Base'!D23,IF(OR('04 — Scenario comparison — Base'!D24="",'04 — Scenario comparison — Base'!D23=""),"",'04 — Scenario comparison — Base'!D24<'04 — Scenario comparison — Base'!D23))="",FALSE,IF(ISERROR('04 — Scenario comparison — Base'!D24<'04 — Scenario comparison — Base'!D23),'04 — Scenario comparison — Base'!D24<'04 — Scenario comparison — Base'!D23,IF(OR('04 — Scenario comparison — Base'!D24="",'04 — Scenario comparison — Base'!D23=""),"",'04 — Scenario comparison — Base'!D24<'04 — Scenario comparison — Base'!D23))),"UNFUNDED LAUNCH",IF(IF(IF(ISERROR('Model inputs'!B74=0),'Model inputs'!B74=0,IF('Model inputs'!B74="","",'Model inputs'!B74=0))="",FALSE,IF(ISERROR('Model inputs'!B74=0),'Model inputs'!B74=0,IF('Model inputs'!B74="","",'Model inputs'!B74=0))),"Cash-positive steady state; not guaranteed runway","Finite burn runway; steady-state assumption")) -> Cash-positive steady state; not guaranteed runway
A33: TS Six month funding bootstrap | B33: ='04 — Scenario comparison — Base'!B23+'01 — Editable assumptions — USD'!B41*'03 — Digital unit economics and'!B29 -> 616.011 | C33: ='04 — Scenario comparison — Base'!C23+'Model inputs'!B91*'Model inputs'!B73 -> 1473.0647 | D33: ='04 — Scenario comparison — Base'!D23+'Model inputs'!B90*'Model inputs'!B72 -> 856.91396
A34: TS Six month funding founder | B34: ='04 — Scenario comparison — Base'!B23+'01 — Editable assumptions — USD'!B41*'03 — Digital unit economics and'!B30 -> 14399.151 | C34: ='04 — Scenario comparison — Base'!C23+'Model inputs'!B91*'Model inputs'!B75 -> 19473.065 | D34: ='04 — Scenario comparison — Base'!D23+'Model inputs'!B90*'Model inputs'!B74 -> 856.91396
A35: TS Ramp funding bootstrap | B35: ='01 — Editable assumptions — USD'!B42*'03 — Digital unit economics and'!B40+'04 — Scenario comparison — Base'!B33 -> 2416.011 | C35: ='Model inputs'!B97*'Model inputs'!B93+'04 — Scenario comparison — Base'!C33 -> 2223.0647 | D35: ='Model inputs'!B96*'Model inputs'!B92+'04 — Scenario comparison — Base'!D33 -> 8056.914
A36: TS Ramp funding founder | B36: ='01 — Editable assumptions — USD'!B42*'03 — Digital unit economics and'!B41+'04 — Scenario comparison — Base'!B34 -> 25199.151 | C36: ='Model inputs'!B97*'Model inputs'!B95+'04 — Scenario comparison — Base'!C34 -> 29223.065 | D36: ='Model inputs'!B96*'Model inputs'!B94+'04 — Scenario comparison — Base'!D34 -> 17056.914

Sheet 01 — Editable assumptions — USD
A1: 01 — Editable assumptions — USD, not actuals
A2: TicketStub — neatHack Business Plan — 2026-10-11 · Main Scenario
A4: Variable / dimension | B4: Value
A5: TS Monthly visits | B5: ='04 — Scenario comparison — Base'!B5 -> 10000
A6: TS Studio start rate | B6: ='04 — Scenario comparison — Base'!B6 -> 0.1
A7: TS Paid conversion of visits | B7: ='04 — Scenario comparison — Base'!B7 -> 0.02
A8: TS Initial images per start | B8: =1 -> 1
A9: TS Expected revisions per start | B9: =1 -> 1
A10: TS Chats per start | B10: ='04 — Scenario comparison — Base'!B9 -> 4
A11: TS Digital price | B11: =9 -> 9
A12: TS Payment rate | B12: =0.029 -> 0.029
A13: TS Payment fixed fee | B13: =0.3 -> 0.3
A14: TS Digital refund allowance | B14: =0.02 -> 0.02
A15: TS Variable support per order | B15: =0.15 -> 0.15
A16: TS Variable delivery per order | B16: =0.03 -> 0.03
A17: TS Variable email per order | B17: =0.02 -> 0.02
A18: TS Research input tokens | B18: =4000 -> 4000
A19: TS Research output tokens | B19: =600 -> 600
A20: TS Chat input tokens | B20: =3000 -> 3000
A21: TS Chat output tokens | B21: =300 -> 300
A22: TS Text input rate per million tokens | B22: =2 -> 2
A23: TS Text output rate per million tokens | B23: =10 -> 10
A24: TS Image text tokens | B24: =150 -> 150
A25: TS Image output tokens | B25: =4000 -> 4000
A26: TS Image input tokens | B26: =0 -> 0
A27: TS Image text rate per million tokens | B27: =5 -> 5
A28: TS Image output rate per million tokens | B28: =30 -> 30
A29: TS Image input rate per million tokens | B29: =8 -> 8
A30: TS Funding allowance | B30: =0.06 -> 0.06
A31: TS Billed retry rate | B31: =0 -> 0
A32: TS Monthly marketing | B32: ='04 — Scenario comparison — Base'!B18 -> 300
A33: TS Hypothetical opening cash | B33: ='04 — Scenario comparison — Base'!B24 -> 1000
A34: TS Alternative opening cash zero | B34: =0 -> 0
A35: TS Alternative opening cash funded | B35: =5000 -> 5000
A36: TS Founder cash pay bootstrap | B36: =0 -> 0
A37: TS Founder cash pay sensitivity | B37: =3000 -> 3000
A38: TS Contingency reserve | B38: =500 -> 500
A39: TS Payout float days | B39: =7 -> 7
A40: TS Cash month days | B40: =30 -> 30
A41: TS Postlaunch funding months | B41: =6 -> 6
...

Sheet 02 — Fixed monthly budgets — es
A1: 02 — Fixed monthly budgets — estimates
A2: TicketStub — neatHack Business Plan — 2026-10-11 · Main Scenario
A4: Variable / dimension | B4: TS Fixed budget amount
A5: Data and API licensing contingency | B5: =40 -> 40
A6: Database backup and base storage | B6: =30 -> 30
A7: Development AI and tools | B7: =60 -> 60
A8: Domain admin and accounting | B8: =20 -> 20
A9: Email base provision | B9: =20 -> 20
A10: Hosting | B10: =80 -> 80
A11: Monitoring traces and security | B11: =50 -> 50

Sheet 03 — Digital unit economics and
A1: 03 — Digital unit economics and funding — monthly assumptions
A2: TicketStub — neatHack Business Plan — 2026-10-11 · Main Scenario
A4: Variable / dimension | B4: Value
A5: TS Research cost per start | B5: ='01 — Editable assumptions — USD'!B18*'01 — Editable assumptions — USD'!B22/1000000+'01 — Editable assumptions — USD'!B19*'01 — Editable assumptions — USD'!B23/1000000 -> 0.014
A6: TS Chat cost per call | B6: ='01 — Editable assumptions — USD'!B20*'01 — Editable assumptions — USD'!B22/1000000+'01 — Editable assumptions — USD'!B21*'01 — Editable assumptions — USD'!B23/1000000 -> 0.009
A7: TS Image cost per generation | B7: ='01 — Editable assumptions — USD'!B24*'01 — Editable assumptions — USD'!B27/1000000+'01 — Editable assumptions — USD'!B25*'01 — Editable assumptions — USD'!B28/1000000+'01 — Editable assumptions — USD'!B26*'01 — Editable assumptions — USD'!B29/1000000 -> 0.12075
A8: TS Images per start | B8: ='01 — Editable assumptions — USD'!B8+'01 — Editable assumptions — USD'!B9 -> 2
A9: TS AI cost per start | B9: =('03 — Digital unit economics and'!B5+'04 — Scenario comparison — Base'!B9*'03 — Digital unit economics and'!B6+'03 — Digital unit economics and'!B8*'03 — Digital unit economics and'!B7)*(1+'01 — Editable assumptions — USD'!B30)*(1+'01 — Editable assumptions — USD'!B31) -> 0.30899
A10: TS Studio starts | B10: ='04 — Scenario comparison — Base'!B5*'04 — Scenario comparison — Base'!B6 -> 1000
A11: TS Digital orders | B11: ='04 — Scenario comparison — Base'!B5*'04 — Scenario comparison — Base'!B7 -> 200
A12: TS Monthly digital revenue | B12: ='03 — Digital unit economics and'!B11*'01 — Editable assumptions — USD'!B11 -> 1800
A13: TS Monthly AI spend | B13: ='03 — Digital unit economics and'!B10*'03 — Digital unit economics and'!B9 -> 308.99
A14: TS AI cost per paid order | B14: =IFERROR('03 — Digital unit economics and'!B13/'03 — Digital unit economics and'!B11,"") -> 1.54495
A15: TS Payment fee per order | B15: ='01 — Editable assumptions — USD'!B11*'01 — Editable assumptions — USD'!B12+'01 — Editable assumptions — USD'!B13 -> 0.561
A16: TS Refund allowance per order | B16: ='01 — Editable assumptions — USD'!B11*'01 — Editable assumptions — USD'!B14 -> 0.18
A17: TS Variable operations per order | B17: ='01 — Editable assumptions — USD'!B15+'01 — Editable assumptions — USD'!B16+'01 — Editable assumptions — USD'!B17 -> 0.2
A18: TS Digital contribution per order | B18: ='01 — Editable assumptions — USD'!B11-'03 — Digital unit economics and'!B15-'03 — Digital unit economics and'!B16-'03 — Digital unit economics and'!B17-'03 — Digital unit economics and'!B14 -> 6.51405
A19: TS Digital contribution margin | B19: =IFERROR('03 — Digital unit economics and'!B18/'01 — Editable assumptions — USD'!B11,"") -> 0.72378333
A20: TS Monthly contribution | B20: ='03 — Digital unit economics and'!B11*'03 — Digital unit economics and'!B18 -> 1302.81
A21: TS Monthly variable costs | B21: ='03 — Digital unit economics and'!B13+'03 — Digital unit economics and'!B11*('03 — Digital unit economics and'!B15+'03 — Digital unit economics and'!B16+'03 — Digital unit economics and'!B17) -> 497.19
A22: TS Fixed monthly budget | B22: =SUM('02 — Fixed monthly budgets — es'!B5,'02 — Fixed monthly budgets — es'!B6,'02 — Fixed monthly budgets — es'!B7,'02 — Fixed monthly budgets — es'!B8,'02 — Fixed monthly budgets — es'!B9,'02 — Fixed monthly budgets — es'!B10,'02 — Fixed monthly budgets — es'!B11) -> 300
A23: TS Monthly operating profit bootstrap | B23: ='03 — Digital unit economics and'!B20-'03 — Digital unit economics and'!B22-'04 — Scenario comparison — Base'!B18-'01 — Editable assumptions — USD'!B36 -> 702.81
A24: TS Monthly operating profit founder | B24: ='03 — Digital unit economics and'!B20-'03 — Digital unit economics and'!B22-'04 — Scenario comparison — Base'!B18-'01 — Editable assumptions — USD'!B37 -> -2297.19
A25: TS Break-even orders bootstrap | B25: =IF(IF(IF(ISERROR('03 — Digital unit economics and'!B18>0),'03 — Digital unit economics and'!B18>0,IF('03 — Digital unit economics and'!B18="","",'03 — Digital unit economics and'!B18>0))="",FALSE,IF(ISERROR('03 — Digital unit economics and'!B18>0),'03 — Digital unit economics and'!B18>0,IF('03 — Digital unit economics and'!B18="","",'03 — Digital unit economics and'!B18>0))),CEILING(('03 — Digital unit economics and'!B22+'04 — Scenario comparison — Base'!B18+'01 — Editable assumptions — USD'!B36)/'03 — Digital unit economics and'!B18,1),"") -> 93
A26: TS Break-even orders founder | B26: =IF(IF(IF(ISERROR('03 — Digital unit economics and'!B18>0),'03 — Digital unit economics and'!B18>0,IF('03 — Digital unit economics and'!B18="","",'03 — Digital unit economics and'!B18>0))="",FALSE,IF(ISERROR('03 — Digital unit economics and'!B18>0),'03 — Digital unit economics and'!B18>0,IF('03 — Digital unit economics and'!B18="","",'03 — Digital unit economics and'!B18>0))),CEILING(('03 — Digital unit economics and'!B22+'04 — Scenario comparison — Base'!B18+'01 — Editable assumptions — USD'!B37)/'03 — Digital unit economics and'!B18,1),"") -> 553
A27: TS Economics reconciliation | B27: ='03 — Digital unit economics and'!B12-'03 — Digital unit economics and'!B21-'03 — Digital unit economics and'!B20 -> -2.2737368e-13
A28: TS Launch reserve | B28: ='01 — Editable assumptions — USD'!B38+'01 — Editable assumptions — USD'!B39/'01 — Editable assumptions — USD'!B40*'03 — Digital unit economics and'!B21 -> 616.011
A29: TS Monthly burn bootstrap | B29: =MAX(0,-'03 — Digital unit economics and'!B23) -> 0
A30: TS Monthly burn founder | B30: =MAX(0,-'03 — Digital unit economics and'!B24) -> 2297.19
A31: TS Runway months bootstrap | B31: =IF(IF(IF(ISERROR('03 — Digital unit economics and'!B29>0),'03 — Digital unit economics and'!B29>0,IF('03 — Digital unit economics and'!B29="","",'03 — Digital unit economics and'!B29>0))="",FALSE,IF(ISERROR('03 — Digital unit economics and'!B29>0),'03 — Digital unit economics and'!B29>0,IF('03 — Digital unit economics and'!B29="","",'03 — Digital unit economics and'!B29>0))),MAX(0,'04 — Scenario comparison — Base'!B24-'03 — Digital unit economics and'!B28)/'03 — Digital unit economics and'!B29,"")
A32: TS Runway months founder | B32: =IF(IF(IF(ISERROR('03 — Digital unit economics and'!B30>0),'03 — Digital unit economics and'!B30>0,IF('03 — Digital unit economics and'!B30="","",'03 — Digital unit economics and'!B30>0))="",FALSE,IF(ISERROR('03 — Digital unit economics and'!B30>0),'03 — Digital unit economics and'!B30>0,IF('03 — Digital unit economics and'!B30="","",'03 — Digital unit economics and'!B30>0))),MAX(0,'04 — Scenario comparison — Base'!B24-'03 — Digital unit economics and'!B28)/'03 — Digital unit economics and'!B30,"") -> 0.16715596
A33: TS Runway at zero bootstrap | B33: =IF(IF(IF(ISERROR('03 — Digital unit economics and'!B29>0),'03 — Digital unit economics and'!B29>0,IF('03 — Digital unit economics and'!B29="","",'03 — Digital unit economics and'!B29>0))="",FALSE,IF(ISERROR('03 — Digital unit economics and'!B29>0),'03 — Digital unit economics and'!B29>0,IF('03 — Digital unit economics and'!B29="","",'03 — Digital unit economics and'!B29>0))),MAX(0,'01 — Editable assumptions — USD'!B34-'03 — Digital unit economics and'!B28)/'03 — Digital unit economics and'!B29,"")
A34: TS Runway at zero founder | B34: =IF(IF(IF(ISERROR('03 — Digital unit economics and'!B30>0),'03 — Digital unit economics and'!B30>0,IF('03 — Digital unit economics and'!B30="","",'03 — Digital unit economics and'!B30>0))="",FALSE,IF(ISERROR('03 — Digital unit economics and'!B30>0),'03 — Digital unit economics and'!B30>0,IF('03 — Digital unit economics and'!B30="","",'03 — Digital unit economics and'!B30>0))),MAX(0,'01 — Editable assumptions — USD'!B34-'03 — Digital unit economics and'!B28)/'03 — Digital unit economics and'!B30,"") -> 0
A35: TS Runway at funded bootstrap | B35: =IF(IF(IF(ISERROR('03 — Digital unit economics and'!B29>0),'03 — Digital unit economics and'!B29>0,IF('03 — Digital unit economics and'!B29="","",'03 — Digital unit economics and'!B29>0))="",FALSE,IF(ISERROR('03 — Digital unit economics and'!B29>0),'03 — Digital unit economics and'!B29>0,IF('03 — Digital unit economics and'!B29="","",'03 — Digital unit economics and'!B29>0))),MAX(0,'01 — Editable assumptions — USD'!B35-'03 — Digital unit economics and'!B28)/'03 — Digital unit economics and'!B29,"")
A36: TS Runway at funded founder | B36: =IF(IF(IF(ISERROR('03 — Digital unit economics and'!B30>0),'03 — Digital unit economics and'!B30>0,IF('03 — Digital unit economics and'!B30="","",'03 — Digital unit economics and'!B30>0))="",FALSE,IF(ISERROR('03 — Digital unit economics and'!B30>0),'03 — Digital unit economics and'!B30>0,IF('03 — Digital unit economics and'!B30="","",'03 — Digital unit economics and'!B30>0))),MAX(0,'01 — Editable assumptions — USD'!B35-'03 — Digital unit economics and'!B28)/'03 — Digital unit economics and'!B30,"") -> 1.9084138
A37: TS Launch funding gap | B37: =MAX(0,'03 — Digital unit economics and'!B28-'04 — Scenario comparison — Base'!B24) -> 0
A38: TS Six month funding bootstrap | B38: ='03 — Digital unit economics and'!B28+'01 — Editable assumptions — USD'!B41*'03 — Digital unit economics and'!B29 -> 616.011
A39: TS Six month funding founder | B39: ='03 — Digital unit economics and'!B28+'01 — Editable assumptions — USD'!B41*'03 — Digital unit economics and'!B30 -> 14399.151
A40: TS Prelaunch monthly burn bootstrap | B40: ='03 — Digital unit economics and'!B22+'04 — Scenario comparison — Base'!B18+'01 — Editable assumptions — USD'!B36 -> 600
A41: TS Prelaunch monthly burn founder | B41: ='03 — Digital unit economics and'!B22+'04 — Scenario comparison — Base'!B18+'01 — Editable assumptions — USD'!B37 -> 3600
...

Sheet 05 — One-factor sensitivities —
A1: 05 — One-factor sensitivities — editable assumptions
A2: TicketStub — neatHack Business Plan — 2026-10-11 · Main Scenario
A4: Variable / dimension | B4: TS Sens Traffic multiplier | C4: TS Sens Conversion multiplier | D4: TS Sens Start multiplier | E4: TS Sens Images multiplier | F4: TS Sens Chats multiplier | G4: TS Sens Image output multiplier | H4: TS Sens Funding allowance | I4: TS Sens Image input tokens | J4: TS Sens Retry rate | K4: TS Sens Visits | L4: TS Sens Orders | M4: TS Sens Starts | N4: TS Sens Image cost | O4: TS Sens AI spend | P4: TS Sens AI per order | Q4: TS Sens Revenue | R4: TS Sens Contribution per order | S4: TS Sens Operating profit | T4: TS Sens Profit change | U4: TS Sens Founder profit
A5: Baseline | B5: =1 -> 1 | C5: =1 -> 1 | D5: =1 -> 1 | E5: =1 -> 1 | F5: =1 -> 1 | G5: =1 -> 1 | H5: =IF('01 — Editable assumptions — USD'!B30="","",'01 — Editable assumptions — USD'!B30) -> 0.06 | I5: =IF('01 — Editable assumptions — USD'!B26="","",'01 — Editable assumptions — USD'!B26) -> 0 | J5: =IF('01 — Editable assumptions — USD'!B31="","",'01 — Editable assumptions — USD'!B31) -> 0 | K5: ='04 — Scenario comparison — Base'!B5*'05 — One-factor sensitivities —'!B5 -> 10000 | L5: ='05 — One-factor sensitivities —'!K5*'04 — Scenario comparison — Base'!B7*'05 — One-factor sensitivities —'!C5 -> 200 | M5: ='05 — One-factor sensitivities —'!K5*'04 — Scenario comparison — Base'!B6*'05 — One-factor sensitivities —'!D5 -> 1000 | N5: ='01 — Editable assumptions — USD'!B24*'01 — Editable assumptions — USD'!B27/1000000+'01 — Editable assumptions — USD'!B25*'05 — One-factor sensitivities —'!G5*'01 — Editable assumptions — USD'!B28/1000000+'05 — One-factor sensitivities —'!I5*'01 — Editable assumptions — USD'!B29/1000000 -> 0.12075 | O5: ='05 — One-factor sensitivities —'!M5*('03 — Digital unit economics and'!B5+'04 — Scenario comparison — Base'!B9*'05 — One-factor sensitivities —'!F5*'03 — Digital unit economics and'!B6+'04 — Scenario comparison — Base'!B8*'05 — One-factor sensitivities —'!E5*'05 — One-factor sensitivities —'!N5)*(1+'05 — One-factor sensitivities —'!H5)*(1+'05 — One-factor sensitivities —'!J5) -> 308.99 | P5: =IFERROR('05 — One-factor sensitivities —'!O5/'05 — One-factor sensitivities —'!L5,"") -> 1.54495 | Q5: ='05 — One-factor sensitivities —'!L5*'01 — Editable assumptions — USD'!B11 -> 1800 | R5: ='01 — Editable assumptions — USD'!B11-'03 — Digital unit economics and'!B15-'03 — Digital unit economics and'!B16-'03 — Digital unit economics and'!B17-'05 — One-factor sensitivities —'!P5 -> 6.51405 | S5: ='05 — One-factor sensitivities —'!L5*('01 — Editable assumptions — USD'!B11-'03 — Digital unit economics and'!B15-'03 — Digital unit economics and'!B16-'03 — Digital unit economics and'!B17)-'05 — One-factor sensitivities —'!O5-'04 — Scenario comparison — Base'!B17-'04 — Scenario comparison — Base'!B18-'01 — Editable assumptions — USD'!B36 -> 702.81 | T5: ='05 — One-factor sensitivities —'!S5-'04 — Scenario comparison — Base'!B19 -> 0 | U5: ='05 — One-factor sensitivities —'!S5+'01 — Editable assumptions — USD'!B36-'01 — Editable assumptions — USD'!B37 -> -2297.19
A6: Billed retries 10 percent | B6: =1 -> 1 | C6: =1 -> 1 | D6: =1 -> 1 | E6: =1 -> 1 | F6: =1 -> 1 | G6: =1 -> 1 | H6: =IF('01 — Editable assumptions — USD'!B30="","",'01 — Editable assumptions — USD'!B30) -> 0.06 | I6: =IF('01 — Editable assumptions — USD'!B26="","",'01 — Editable assumptions — USD'!B26) -> 0 | J6: =0.1 -> 0.1 | K6: ='04 — Scenario comparison — Base'!B5*'05 — One-factor sensitivities —'!B6 -> 10000 | L6: ='05 — One-factor sensitivities —'!K6*'04 — Scenario comparison — Base'!B7*'05 — One-factor sensitivities —'!C6 -> 200 | M6: ='05 — One-factor sensitivities —'!K6*'04 — Scenario comparison — Base'!B6*'05 — One-factor sensitivities —'!D6 -> 1000 | N6: ='01 — Editable assumptions — USD'!B24*'01 — Editable assumptions — USD'!B27/1000000+'01 — Editable assumptions — USD'!B25*'05 — One-factor sensitivities —'!G6*'01 — Editable assumptions — USD'!B28/1000000+'05 — One-factor sensitivities —'!I6*'01 — Editable assumptions — USD'!B29/1000000 -> 0.12075 | O6: ='05 — One-factor sensitivities —'!M6*('03 — Digital unit economics and'!B5+'04 — Scenario comparison — Base'!B9*'05 — One-factor sensitivities —'!F6*'03 — Digital unit economics and'!B6+'04 — Scenario comparison — Base'!B8*'05 — One-factor sensitivities —'!E6*'05 — One-factor sensitivities —'!N6)*(1+'05 — One-factor sensitivities —'!H6)*(1+'05 — One-factor sensitivities —'!J6) -> 339.889 | P6: =IFERROR('05 — One-factor sensitivities —'!O6/'05 — One-factor sensitivities —'!L6,"") -> 1.699445 | Q6: ='05 — One-factor sensitivities —'!L6*'01 — Editable assumptions — USD'!B11 -> 1800 | R6: ='01 — Editable assumptions — USD'!B11-'03 — Digital unit economics and'!B15-'03 — Digital unit economics and'!B16-'03 — Digital unit economics and'!B17-'05 — One-factor sensitivities —'!P6 -> 6.359555 | S6: ='05 — One-factor sensitivities —'!L6*('01 — Editable assumptions — USD'!B11-'03 — Digital unit economics and'!B15-'03 — Digital unit economics and'!B16-'03 — Digital unit economics and'!B17)-'05 — One-factor sensitivities —'!O6-'04 — Scenario comparison — Base'!B17-'04 — Scenario comparison — Base'!B18-'01 — Editable assumptions — USD'!B36 -> 671.911 | T6: ='05 — One-factor sensitivities —'!S6-'04 — Scenario comparison — Base'!B19 -> -30.899 | U6: ='05 — One-factor sensitivities —'!S6+'01 — Editable assumptions — USD'!B36-'01 — Editable assumptions — USD'!B37 -> -2328.089
A7: Chats x2 — Base eight per start | B7: =1 -> 1 | C7: =1 -> 1 | D7: =1 -> 1 | E7: =1 -> 1 | F7: =2 -> 2 | G7: =1 -> 1 | H7: =IF('01 — Editable assumptions — USD'!B30="","",'01 — Editable assumptions — USD'!B30) -> 0.06 | I7: =IF('01 — Editable assumptions — USD'!B26="","",'01 — Editable assumptions — USD'!B26) -> 0 | J7: =IF('01 — Editable assumptions — USD'!B31="","",'01 — Editable assumptions — USD'!B31) -> 0 | K7: ='04 — Scenario comparison — Base'!B5*'05 — One-factor sensitivities —'!B7 -> 10000 | L7: ='05 — One-factor sensitivities —'!K7*'04 — Scenario comparison — Base'!B7*'05 — One-factor sensitivities —'!C7 -> 200 | M7: ='05 — One-factor sensitivities —'!K7*'04 — Scenario comparison — Base'!B6*'05 — One-factor sensitivities —'!D7 -> 1000 | N7: ='01 — Editable assumptions — USD'!B24*'01 — Editable assumptions — USD'!B27/1000000+'01 — Editable assumptions — USD'!B25*'05 — One-factor sensitivities —'!G7*'01 — Editable assumptions — USD'!B28/1000000+'05 — One-factor sensitivities —'!I7*'01 — Editable assumptions — USD'!B29/1000000 -> 0.12075 | O7: ='05 — One-factor sensitivities —'!M7*('03 — Digital unit economics and'!B5+'04 — Scenario comparison — Base'!B9*'05 — One-factor sensitivities —'!F7*'03 — Digital unit economics and'!B6+'04 — Scenario comparison — Base'!B8*'05 — One-factor sensitivities —'!E7*'05 — One-factor sensitivities —'!N7)*(1+'05 — One-factor sensitivities —'!H7)*(1+'05 — One-factor sensitivities —'!J7) -> 347.15 | P7: =IFERROR('05 — One-factor sensitivities —'!O7/'05 — One-factor sensitivities —'!L7,"") -> 1.73575 | Q7: ='05 — One-factor sensitivities —'!L7*'01 — Editable assumptions — USD'!B11 -> 1800 | R7: ='01 — Editable assumptions — USD'!B11-'03 — Digital unit economics and'!B15-'03 — Digital unit economics and'!B16-'03 — Digital unit economics and'!B17-'05 — One-factor sensitivities —'!P7 -> 6.32325 | S7: ='05 — One-factor sensitivities —'!L7*('01 — Editable assumptions — USD'!B11-'03 — Digital unit economics and'!B15-'03 — Digital unit economics and'!B16-'03 — Digital unit economics and'!B17)-'05 — One-factor sensitivities —'!O7-'04 — Scenario comparison — Base'!B17-'04 — Scenario comparison — Base'!B18-'01 — Editable assumptions — USD'!B36 -> 664.65 | T7: ='05 — One-factor sensitivities —'!S7-'04 — Scenario comparison — Base'!B19 -> -38.16 | U7: ='05 — One-factor sensitivities —'!S7+'01 — Editable assumptions — USD'!B36-'01 — Editable assumptions — USD'!B37 -> -2335.35
A8: Conversion x0.5 — Base 1 percent | B8: =1 -> 1 | C8: =0.5 -> 0.5 | D8: =1 -> 1 | E8: =1 -> 1 | F8: =1 -> 1 | G8: =1 -> 1 | H8: =IF('01 — Editable assumptions — USD'!B30="","",'01 — Editable assumptions — USD'!B30) -> 0.06 | I8: =IF('01 — Editable assumptions — USD'!B26="","",'01 — Editable assumptions — USD'!B26) -> 0 | J8: =IF('01 — Editable assumptions — USD'!B31="","",'01 — Editable assumptions — USD'!B31) -> 0 | K8: ='04 — Scenario comparison — Base'!B5*'05 — One-factor sensitivities —'!B8 -> 10000 | L8: ='05 — One-factor sensitivities —'!K8*'04 — Scenario comparison — Base'!B7*'05 — One-factor sensitivities —'!C8 -> 100 | M8: ='05 — One-factor sensitivities —'!K8*'04 — Scenario comparison — Base'!B6*'05 — One-factor sensitivities —'!D8 -> 1000 | N8: ='01 — Editable assumptions — USD'!B24*'01 — Editable assumptions — USD'!B27/1000000+'01 — Editable assumptions — USD'!B25*'05 — One-factor sensitivities —'!G8*'01 — Editable assumptions — USD'!B28/1000000+'05 — One-factor sensitivities —'!I8*'01 — Editable assumptions — USD'!B29/1000000 -> 0.12075 | O8: ='05 — One-factor sensitivities —'!M8*('03 — Digital unit economics and'!B5+'04 — Scenario comparison — Base'!B9*'05 — One-factor sensitivities —'!F8*'03 — Digital unit economics and'!B6+'04 — Scenario comparison — Base'!B8*'05 — One-factor sensitivities —'!E8*'05 — One-factor sensitivities —'!N8)*(1+'05 — One-factor sensitivities —'!H8)*(1+'05 — One-factor sensitivities —'!J8) -> 308.99 | P8: =IFERROR('05 — One-factor sensitivities —'!O8/'05 — One-factor sensitivities —'!L8,"") -> 3.0899 | Q8: ='05 — One-factor sensitivities —'!L8*'01 — Editable assumptions — USD'!B11 -> 900 | R8: ='01 — Editable assumptions — USD'!B11-'03 — Digital unit economics and'!B15-'03 — Digital unit economics and'!B16-'03 — Digital unit economics and'!B17-'05 — One-factor sensitivities —'!P8 -> 4.9691 | S8: ='05 — One-factor sensitivities —'!L8*('01 — Editable assumptions — USD'!B11-'03 — Digital unit economics and'!B15-'03 — Digital unit economics and'!B16-'03 — Digital unit economics and'!B17)-'05 — One-factor sensitivities —'!O8-'04 — Scenario comparison — Base'!B17-'04 — Scenario comparison — Base'!B18-'01 — Editable assumptions — USD'!B36 -> -103.09 | T8: ='05 — One-factor sensitivities —'!S8-'04 — Scenario comparison — Base'!B19 -> -805.9 | U8: ='05 — One-factor sensitivities —'!S8+'01 — Editable assumptions — USD'!B36-'01 — Editable assumptions — USD'!B37 -> -3103.09
A9: Conversion x1.5 — Base 3 percent | B9: =1 -> 1 | C9: =1.5 -> 1.5 | D9: =1 -> 1 | E9: =1 -> 1 | F9: =1 -> 1 | G9: =1 -> 1 | H9: =IF('01 — Editable assumptions — USD'!B30="","",'01 — Editable assumptions — USD'!B30) -> 0.06 | I9: =IF('01 — Editable assumptions — USD'!B26="","",'01 — Editable assumptions — USD'!B26) -> 0 | J9: =IF('01 — Editable assumptions — USD'!B31="","",'01 — Editable assumptions — USD'!B31) -> 0 | K9: ='04 — Scenario comparison — Base'!B5*'05 — One-factor sensitivities —'!B9 -> 10000 | L9: ='05 — One-factor sensitivities —'!K9*'04 — Scenario comparison — Base'!B7*'05 — One-factor sensitivities —'!C9 -> 300 | M9: ='05 — One-factor sensitivities —'!K9*'04 — Scenario comparison — Base'!B6*'05 — One-factor sensitivities —'!D9 -> 1000 | N9: ='01 — Editable assumptions — USD'!B24*'01 — Editable assumptions — USD'!B27/1000000+'01 — Editable assumptions — USD'!B25*'05 — One-factor sensitivities —'!G9*'01 — Editable assumptions — USD'!B28/1000000+'05 — One-factor sensitivities —'!I9*'01 — Editable assumptions — USD'!B29/1000000 -> 0.12075 | O9: ='05 — One-factor sensitivities —'!M9*('03 — Digital unit economics and'!B5+'04 — Scenario comparison — Base'!B9*'05 — One-factor sensitivities —'!F9*'03 — Digital unit economics and'!B6+'04 — Scenario comparison — Base'!B8*'05 — One-factor sensitivities —'!E9*'05 — One-factor sensitivities —'!N9)*(1+'05 — One-factor sensitivities —'!H9)*(1+'05 — One-factor sensitivities —'!J9) -> 308.99 | P9: =IFERROR('05 — One-factor sensitivities —'!O9/'05 — One-factor sensitivities —'!L9,"") -> 1.0299667 | Q9: ='05 — One-factor sensitivities —'!L9*'01 — Editable assumptions — USD'!B11 -> 2700 | R9: ='01 — Editable assumptions — USD'!B11-'03 — Digital unit economics and'!B15-'03 — Digital unit economics and'!B16-'03 — Digital unit economics and'!B17-'05 — One-factor sensitivities —'!P9 -> 7.0290333 | S9: ='05 — One-factor sensitivities —'!L9*('01 — Editable assumptions — USD'!B11-'03 — Digital unit economics and'!B15-'03 — Digital unit economics and'!B16-'03 — Digital unit economics and'!B17)-'05 — One-factor sensitivities —'!O9-'04 — Scenario comparison — Base'!B17-'04 — Scenario comparison — Base'!B18-'01 — Editable assumptions — USD'!B36 -> 1508.71 | T9: ='05 — One-factor sensitivities —'!S9-'04 — Scenario comparison — Base'!B19 -> 805.9 | U9: ='05 — One-factor sensitivities —'!S9+'01 — Editable assumptions — USD'!B36-'01 — Editable assumptions — USD'!B37 -> -1491.29
A10: Double traffic | B10: =2 -> 2 | C10: =1 -> 1 | D10: =1 -> 1 | E10: =1 -> 1 | F10: =1 -> 1 | G10: =1 -> 1 | H10: =IF('01 — Editable assumptions — USD'!B30="","",'01 — Editable assumptions — USD'!B30) -> 0.06 | I10: =IF('01 — Editable assumptions — USD'!B26="","",'01 — Editable assumptions — USD'!B26) -> 0 | J10: =IF('01 — Editable assumptions — USD'!B31="","",'01 — Editable assumptions — USD'!B31) -> 0 | K10: ='04 — Scenario comparison — Base'!B5*'05 — One-factor sensitivities —'!B10 -> 20000 | L10: ='05 — One-factor sensitivities —'!K10*'04 — Scenario comparison — Base'!B7*'05 — One-factor sensitivities —'!C10 -> 400 | M10: ='05 — One-factor sensitivities —'!K10*'04 — Scenario comparison — Base'!B6*'05 — One-factor sensitivities —'!D10 -> 2000 | N10: ='01 — Editable assumptions — USD'!B24*'01 — Editable assumptions — USD'!B27/1000000+'01 — Editable assumptions — USD'!B25*'05 — One-factor sensitivities —'!G10*'01 — Editable assumptions — USD'!B28/1000000+'05 — One-factor sensitivities —'!I10*'01 — Editable assumptions — USD'!B29/1000000 -> 0.12075 | O10: ='05 — One-factor sensitivities —'!M10*('03 — Digital unit economics and'!B5+'04 — Scenario comparison — Base'!B9*'05 — One-factor sensitivities —'!F10*'03 — Digital unit economics and'!B6+'04 — Scenario comparison — Base'!B8*'05 — One-factor sensitivities —'!E10*'05 — One-factor sensitivities —'!N10)*(1+'05 — One-factor sensitivities —'!H10)*(1+'05 — One-factor sensitivities —'!J10) -> 617.98 | P10: =IFERROR('05 — One-factor sensitivities —'!O10/'05 — One-factor sensitivities —'!L10,"") -> 1.54495 | Q10: ='05 — One-factor sensitivities —'!L10*'01 — Editable assumptions — USD'!B11 -> 3600 | R10: ='01 — Editable assumptions — USD'!B11-'03 — Digital unit economics and'!B15-'03 — Digital unit economics and'!B16-'03 — Digital unit economics and'!B17-'05 — One-factor sensitivities —'!P10 -> 6.51405 | S10: ='05 — One-factor sensitivities —'!L10*('01 — Editable assumptions — USD'!B11-'03 — Digital unit economics and'!B15-'03 — Digital unit economics and'!B16-'03 — Digital unit economics and'!B17)-'05 — One-factor sensitivities —'!O10-'04 — Scenario comparison — Base'!B17-'04 — Scenario comparison — Base'!B18-'01 — Editable assumptions — USD'!B36 -> 2005.62 | T10: ='05 — One-factor sensitivities —'!S10-'04 — Scenario comparison — Base'!B19 -> 1302.81 | U10: ='05 — One-factor sensitivities —'!S10+'01 — Editable assumptions — USD'!B36-'01 — Editable assumptions — USD'!B37 -> -994.38
A11: Funding allowance 10 percent | B11: =1 -> 1 | C11: =1 -> 1 | D11: =1 -> 1 | E11: =1 -> 1 | F11: =1 -> 1 | G11: =1 -> 1 | H11: =0.1 -> 0.1 | I11: =IF('01 — Editable assumptions — USD'!B26="","",'01 — Editable assumptions — USD'!B26) -> 0 | J11: =IF('01 — Editable assumptions — USD'!B31="","",'01 — Editable assumptions — USD'!B31) -> 0 | K11: ='04 — Scenario comparison — Base'!B5*'05 — One-factor sensitivities —'!B11 -> 10000 | L11: ='05 — One-factor sensitivities —'!K11*'04 — Scenario comparison — Base'!B7*'05 — One-factor sensitivities —'!C11 -> 200 | M11: ='05 — One-factor sensitivities —'!K11*'04 — Scenario comparison — Base'!B6*'05 — One-factor sensitivities —'!D11 -> 1000 | N11: ='01 — Editable assumptions — USD'!B24*'01 — Editable assumptions — USD'!B27/1000000+'01 — Editable assumptions — USD'!B25*'05 — One-factor sensitivities —'!G11*'01 — Editable assumptions — USD'!B28/1000000+'05 — One-factor sensitivities —'!I11*'01 — Editable assumptions — USD'!B29/1000000 -> 0.12075 | O11: ='05 — One-factor sensitivities —'!M11*('03 — Digital unit economics and'!B5+'04 — Scenario comparison — Base'!B9*'05 — One-factor sensitivities —'!F11*'03 — Digital unit economics and'!B6+'04 — Scenario comparison — Base'!B8*'05 — One-factor sensitivities —'!E11*'05 — One-factor sensitivities —'!N11)*(1+'05 — One-factor sensitivities —'!H11)*(1+'05 — One-factor sensitivities —'!J11) -> 320.65 | P11: =IFERROR('05 — One-factor sensitivities —'!O11/'05 — One-factor sensitivities —'!L11,"") -> 1.60325 | Q11: ='05 — One-factor sensitivities —'!L11*'01 — Editable assumptions — USD'!B11 -> 1800 | R11: ='01 — Editable assumptions — USD'!B11-'03 — Digital unit economics and'!B15-'03 — Digital unit economics and'!B16-'03 — Digital unit economics and'!B17-'05 — One-factor sensitivities —'!P11 -> 6.45575 | S11: ='05 — One-factor sensitivities —'!L11*('01 — Editable assumptions — USD'!B11-'03 — Digital unit economics and'!B15-'03 — Digital unit economics and'!B16-'03 — Digital unit economics and'!B17)-'05 — One-factor sensitivities —'!O11-'04 — Scenario comparison — Base'!B17-'04 — Scenario comparison — Base'!B18-'01 — Editable assumptions — USD'!B36 -> 691.15 | T11: ='05 — One-factor sensitivities —'!S11-'04 — Scenario comparison — Base'!B19 -> -11.66 | U11: ='05 — One-factor sensitivities —'!S11+'01 — Editable assumptions — USD'!B36-'01 — Editable assumptions — USD'!B37 -> -2308.85
A12: Funding allowance zero | B12: =1 -> 1 | C12: =1 -> 1 | D12: =1 -> 1 | E12: =1 -> 1 | F12: =1 -> 1 | G12: =1 -> 1 | H12: =0 -> 0 | I12: =IF('01 — Editable assumptions — USD'!B26="","",'01 — Editable assumptions — USD'!B26) -> 0 | J12: =IF('01 — Editable assumptions — USD'!B31="","",'01 — Editable assumptions — USD'!B31) -> 0 | K12: ='04 — Scenario comparison — Base'!B5*'05 — One-factor sensitivities —'!B12 -> 10000 | L12: ='05 — One-factor sensitivities —'!K12*'04 — Scenario comparison — Base'!B7*'05 — One-factor sensitivities —'!C12 -> 200 | M12: ='05 — One-factor sensitivities —'!K12*'04 — Scenario comparison — Base'!B6*'05 — One-factor sensitivities —'!D12 -> 1000 | N12: ='01 — Editable assumptions — USD'!B24*'01 — Editable assumptions — USD'!B27/1000000+'01 — Editable assumptions — USD'!B25*'05 — One-factor sensitivities —'!G12*'01 — Editable assumptions — USD'!B28/1000000+'05 — One-factor sensitivities —'!I12*'01 — Editable assumptions — USD'!B29/1000000 -> 0.12075 | O12: ='05 — One-factor sensitivities —'!M12*('03 — Digital unit economics and'!B5+'04 — Scenario comparison — Base'!B9*'05 — One-factor sensitivities —'!F12*'03 — Digital unit economics and'!B6+'04 — Scenario comparison — Base'!B8*'05 — One-factor sensitivities —'!E12*'05 — One-factor sensitivities —'!N12)*(1+'05 — One-factor sensitivities —'!H12)*(1+'05 — One-factor sensitivities —'!J12) -> 291.5 | P12: =IFERROR('05 — One-factor sensitivities —'!O12/'05 — One-factor sensitivities —'!L12,"") -> 1.4575 | Q12: ='05 — One-factor sensitivities —'!L12*'01 — Editable assumptions — USD'!B11 -> 1800 | R12: ='01 — Editable assumptions — USD'!B11-'03 — Digital unit economics and'!B15-'03 — Digital unit economics and'!B16-'03 — Digital unit economics and'!B17-'05 — One-factor sensitivities —'!P12 -> 6.6015 | S12: ='05 — One-factor sensitivities —'!L12*('01 — Editable assumptions — USD'!B11-'03 — Digital unit economics and'!B15-'03 — Digital unit economics and'!B16-'03 — Digital unit economics and'!B17)-'05 — One-factor sensitivities —'!O12-'04 — Scenario comparison — Base'!B17-'04 — Scenario comparison — Base'!B18-'01 — Editable assumptions — USD'!B36 -> 720.3 | T12: ='05 — One-factor sensitivities —'!S12-'04 — Scenario comparison — Base'!B19 -> 17.49 | U12: ='05 — One-factor sensitivities —'!S12+'01 — Editable assumptions — USD'!B36-'01 — Editable assumptions — USD'!B37 -> -2279.7
